[2022-10-13 11:54:27,036] {taskinstance.py:1159} INFO - Dependencies all met for <TaskInstance: my_first_dag.create_table manual__2022-10-13T11:54:26.233141+00:00 [queued]>
[2022-10-13 11:54:27,046] {taskinstance.py:1159} INFO - Dependencies all met for <TaskInstance: my_first_dag.create_table manual__2022-10-13T11:54:26.233141+00:00 [queued]>
[2022-10-13 11:54:27,046] {taskinstance.py:1356} INFO - 
--------------------------------------------------------------------------------
[2022-10-13 11:54:27,046] {taskinstance.py:1357} INFO - Starting attempt 1 of 1
[2022-10-13 11:54:27,047] {taskinstance.py:1358} INFO - 
--------------------------------------------------------------------------------
[2022-10-13 11:54:27,069] {taskinstance.py:1377} INFO - Executing <Task(PostgresOperator): create_table> on 2022-10-13 11:54:26.233141+00:00
[2022-10-13 11:54:27,077] {standard_task_runner.py:52} INFO - Started process 140 to run task
[2022-10-13 11:54:27,083] {standard_task_runner.py:79} INFO - Running: ['***', 'tasks', 'run', 'my_first_dag', 'create_table', 'manual__2022-10-13T11:54:26.233141+00:00', '--job-id', '5', '--raw', '--subdir', 'DAGS_FOLDER/user_processing.py', '--cfg-path', '/tmp/tmpdriagyf9', '--error-file', '/tmp/tmpriw6f25k']
[2022-10-13 11:54:27,084] {standard_task_runner.py:80} INFO - Job 5: Subtask create_table
[2022-10-13 11:54:27,136] {task_command.py:369} INFO - Running <TaskInstance: my_first_dag.create_table manual__2022-10-13T11:54:26.233141+00:00 [running]> on host bfbb62eba460
[2022-10-13 11:54:27,194] {taskinstance.py:1571} INFO - Exporting the following env vars:
AIRFLOW_CTX_DAG_OWNER=***
AIRFLOW_CTX_DAG_ID=my_first_dag
AIRFLOW_CTX_TASK_ID=create_table
AIRFLOW_CTX_EXECUTION_DATE=2022-10-13T11:54:26.233141+00:00
AIRFLOW_CTX_TRY_NUMBER=1
AIRFLOW_CTX_DAG_RUN_ID=manual__2022-10-13T11:54:26.233141+00:00
[2022-10-13 11:54:27,202] {base.py:68} INFO - Using connection ID '***' for task execution.
[2022-10-13 11:54:27,206] {taskinstance.py:1889} ERROR - Task failed with exception
Traceback (most recent call last):
  File "/home/airflow/.local/lib/python3.7/site-packages/airflow/providers/postgres/operators/postgres.py", line 92, in execute
    self.hook.run(self.sql, self.autocommit, parameters=self.parameters)
  File "/home/airflow/.local/lib/python3.7/site-packages/airflow/hooks/dbapi.py", line 181, in run
    with closing(self.get_conn()) as conn:
  File "/home/airflow/.local/lib/python3.7/site-packages/airflow/providers/postgres/hooks/postgres.py", line 113, in get_conn
    self.conn = psycopg2.connect(**conn_args)
  File "/home/airflow/.local/lib/python3.7/site-packages/psycopg2/__init__.py", line 122, in connect
    conn = _connect(dsn, connection_factory=connection_factory, **kwasync)
psycopg2.OperationalError: FATAL:  password authentication failed for user "***"

[2022-10-13 11:54:27,213] {taskinstance.py:1400} INFO - Marking task as FAILED. dag_id=my_first_dag, task_id=create_table, execution_date=20221013T115426, start_date=20221013T115427, end_date=20221013T115427
[2022-10-13 11:54:27,222] {standard_task_runner.py:97} ERROR - Failed to execute job 5 for task create_table (FATAL:  password authentication failed for user "***"
; 140)
[2022-10-13 11:54:27,254] {local_task_job.py:156} INFO - Task exited with return code 1
[2022-10-13 11:54:27,302] {local_task_job.py:273} INFO - 0 downstream tasks scheduled from follow-on schedule check
