[2022-10-17 09:01:09,495] {taskinstance.py:1159} INFO - Dependencies all met for <TaskInstance: my_first_dag.is_api_available manual__2022-10-17T09:01:07.365310+00:00 [queued]>
[2022-10-17 09:01:09,502] {taskinstance.py:1159} INFO - Dependencies all met for <TaskInstance: my_first_dag.is_api_available manual__2022-10-17T09:01:07.365310+00:00 [queued]>
[2022-10-17 09:01:09,502] {taskinstance.py:1356} INFO - 
--------------------------------------------------------------------------------
[2022-10-17 09:01:09,503] {taskinstance.py:1357} INFO - Starting attempt 1 of 1
[2022-10-17 09:01:09,503] {taskinstance.py:1358} INFO - 
--------------------------------------------------------------------------------
[2022-10-17 09:01:09,512] {taskinstance.py:1377} INFO - Executing <Task(HttpSensor): is_api_available> on 2022-10-17 09:01:07.365310+00:00
[2022-10-17 09:01:09,517] {standard_task_runner.py:52} INFO - Started process 231 to run task
[2022-10-17 09:01:09,520] {standard_task_runner.py:79} INFO - Running: ['***', 'tasks', 'run', 'my_first_dag', 'is_api_available', 'manual__2022-10-17T09:01:07.365310+00:00', '--job-id', '23', '--raw', '--subdir', 'DAGS_FOLDER/user_processing.py', '--cfg-path', '/tmp/tmp8_m22jiy', '--error-file', '/tmp/tmpto38m41f']
[2022-10-17 09:01:09,520] {standard_task_runner.py:80} INFO - Job 23: Subtask is_api_available
[2022-10-17 09:01:09,556] {task_command.py:369} INFO - Running <TaskInstance: my_first_dag.is_api_available manual__2022-10-17T09:01:07.365310+00:00 [running]> on host e83442a232da
[2022-10-17 09:01:09,603] {taskinstance.py:1571} INFO - Exporting the following env vars:
AIRFLOW_CTX_DAG_OWNER=***
AIRFLOW_CTX_DAG_ID=my_first_dag
AIRFLOW_CTX_TASK_ID=is_api_available
AIRFLOW_CTX_EXECUTION_DATE=2022-10-17T09:01:07.365310+00:00
AIRFLOW_CTX_TRY_NUMBER=1
AIRFLOW_CTX_DAG_RUN_ID=manual__2022-10-17T09:01:07.365310+00:00
[2022-10-17 09:01:09,604] {http.py:97} INFO - Poking: api/
[2022-10-17 09:01:09,619] {taskinstance.py:1889} ERROR - Task failed with exception
Traceback (most recent call last):
  File "/home/airflow/.local/lib/python3.7/site-packages/airflow/sensors/base.py", line 277, in execute
    poke_return = self.poke(context)
  File "/home/airflow/.local/lib/python3.7/site-packages/airflow/providers/http/sensors/http.py", line 112, in poke
    raise exc
  File "/home/airflow/.local/lib/python3.7/site-packages/airflow/providers/http/sensors/http.py", line 103, in poke
    extra_options=self.extra_options,
  File "/home/airflow/.local/lib/python3.7/site-packages/airflow/providers/http/hooks/http.py", line 114, in run
    session = self.get_conn(headers)
  File "/home/airflow/.local/lib/python3.7/site-packages/airflow/providers/http/hooks/http.py", line 68, in get_conn
    conn = self.get_connection(self.http_conn_id)
  File "/home/airflow/.local/lib/python3.7/site-packages/airflow/hooks/base.py", line 67, in get_connection
    conn = Connection.get_connection_from_secrets(conn_id)
  File "/home/airflow/.local/lib/python3.7/site-packages/airflow/models/connection.py", line 430, in get_connection_from_secrets
    raise AirflowNotFoundException(f"The conn_id `{conn_id}` isn't defined")
airflow.exceptions.AirflowNotFoundException: The conn_id `user_api` isn't defined
[2022-10-17 09:01:09,622] {taskinstance.py:1400} INFO - Marking task as FAILED. dag_id=my_first_dag, task_id=is_api_available, execution_date=20221017T090107, start_date=20221017T090109, end_date=20221017T090109
[2022-10-17 09:01:09,629] {standard_task_runner.py:97} ERROR - Failed to execute job 23 for task is_api_available (The conn_id `user_api` isn't defined; 231)
[2022-10-17 09:01:09,652] {local_task_job.py:156} INFO - Task exited with return code 1
[2022-10-17 09:01:09,686] {local_task_job.py:273} INFO - 0 downstream tasks scheduled from follow-on schedule check
