[2022-10-13 11:53:26,313] {taskinstance.py:1159} INFO - Dependencies all met for <TaskInstance: my_first_dag.create_table manual__2022-10-13T11:53:24.255479+00:00 [queued]>
[2022-10-13 11:53:26,320] {taskinstance.py:1159} INFO - Dependencies all met for <TaskInstance: my_first_dag.create_table manual__2022-10-13T11:53:24.255479+00:00 [queued]>
[2022-10-13 11:53:26,320] {taskinstance.py:1356} INFO - 
--------------------------------------------------------------------------------
[2022-10-13 11:53:26,320] {taskinstance.py:1357} INFO - Starting attempt 1 of 1
[2022-10-13 11:53:26,320] {taskinstance.py:1358} INFO - 
--------------------------------------------------------------------------------
[2022-10-13 11:53:26,329] {taskinstance.py:1377} INFO - Executing <Task(PostgresOperator): create_table> on 2022-10-13 11:53:24.255479+00:00
[2022-10-13 11:53:26,345] {standard_task_runner.py:52} INFO - Started process 83 to run task
[2022-10-13 11:53:26,350] {standard_task_runner.py:79} INFO - Running: ['***', 'tasks', 'run', 'my_first_dag', 'create_table', 'manual__2022-10-13T11:53:24.255479+00:00', '--job-id', '3', '--raw', '--subdir', 'DAGS_FOLDER/user_processing.py', '--cfg-path', '/tmp/tmpmrybu5i4', '--error-file', '/tmp/tmphwf3wbxw']
[2022-10-13 11:53:26,351] {standard_task_runner.py:80} INFO - Job 3: Subtask create_table
[2022-10-13 11:53:26,430] {task_command.py:369} INFO - Running <TaskInstance: my_first_dag.create_table manual__2022-10-13T11:53:24.255479+00:00 [running]> on host bfbb62eba460
[2022-10-13 11:53:26,485] {taskinstance.py:1571} INFO - Exporting the following env vars:
AIRFLOW_CTX_DAG_OWNER=***
AIRFLOW_CTX_DAG_ID=my_first_dag
AIRFLOW_CTX_TASK_ID=create_table
AIRFLOW_CTX_EXECUTION_DATE=2022-10-13T11:53:24.255479+00:00
AIRFLOW_CTX_TRY_NUMBER=1
AIRFLOW_CTX_DAG_RUN_ID=manual__2022-10-13T11:53:24.255479+00:00
[2022-10-13 11:53:26,504] {taskinstance.py:1889} ERROR - Task failed with exception
Traceback (most recent call last):
  File "/home/airflow/.local/lib/python3.7/site-packages/airflow/providers/postgres/operators/postgres.py", line 92, in execute
    self.hook.run(self.sql, self.autocommit, parameters=self.parameters)
  File "/home/airflow/.local/lib/python3.7/site-packages/airflow/hooks/dbapi.py", line 181, in run
    with closing(self.get_conn()) as conn:
  File "/home/airflow/.local/lib/python3.7/site-packages/airflow/providers/postgres/hooks/postgres.py", line 86, in get_conn
    conn = deepcopy(self.connection or self.get_connection(conn_id))
  File "/home/airflow/.local/lib/python3.7/site-packages/airflow/hooks/base.py", line 67, in get_connection
    conn = Connection.get_connection_from_secrets(conn_id)
  File "/home/airflow/.local/lib/python3.7/site-packages/airflow/models/connection.py", line 430, in get_connection_from_secrets
    raise AirflowNotFoundException(f"The conn_id `{conn_id}` isn't defined")
airflow.exceptions.AirflowNotFoundException: The conn_id `postgres` isn't defined
[2022-10-13 11:53:26,507] {taskinstance.py:1400} INFO - Marking task as FAILED. dag_id=my_first_dag, task_id=create_table, execution_date=20221013T115324, start_date=20221013T115326, end_date=20221013T115326
[2022-10-13 11:53:26,515] {standard_task_runner.py:97} ERROR - Failed to execute job 3 for task create_table (The conn_id `postgres` isn't defined; 83)
[2022-10-13 11:53:26,531] {local_task_job.py:156} INFO - Task exited with return code 1
[2022-10-13 11:53:26,563] {local_task_job.py:273} INFO - 0 downstream tasks scheduled from follow-on schedule check
