[2022-10-17 10:24:26,869] {taskinstance.py:1159} INFO - Dependencies all met for <TaskInstance: my_first_dag.process_user manual__2022-10-17T10:24:20.577359+00:00 [queued]>
[2022-10-17 10:24:26,875] {taskinstance.py:1159} INFO - Dependencies all met for <TaskInstance: my_first_dag.process_user manual__2022-10-17T10:24:20.577359+00:00 [queued]>
[2022-10-17 10:24:26,875] {taskinstance.py:1356} INFO - 
--------------------------------------------------------------------------------
[2022-10-17 10:24:26,875] {taskinstance.py:1357} INFO - Starting attempt 1 of 1
[2022-10-17 10:24:26,876] {taskinstance.py:1358} INFO - 
--------------------------------------------------------------------------------
[2022-10-17 10:24:26,883] {taskinstance.py:1377} INFO - Executing <Task(PythonOperator): process_user> on 2022-10-17 10:24:20.577359+00:00
[2022-10-17 10:24:26,887] {standard_task_runner.py:52} INFO - Started process 3533 to run task
[2022-10-17 10:24:26,890] {standard_task_runner.py:79} INFO - Running: ['***', 'tasks', 'run', 'my_first_dag', 'process_user', 'manual__2022-10-17T10:24:20.577359+00:00', '--job-id', '80', '--raw', '--subdir', 'DAGS_FOLDER/user_processing.py', '--cfg-path', '/tmp/tmplxg3r6lp', '--error-file', '/tmp/tmp_lim4q7k']
[2022-10-17 10:24:26,891] {standard_task_runner.py:80} INFO - Job 80: Subtask process_user
[2022-10-17 10:24:26,923] {task_command.py:369} INFO - Running <TaskInstance: my_first_dag.process_user manual__2022-10-17T10:24:20.577359+00:00 [running]> on host 48b5b9061ccc
[2022-10-17 10:24:26,973] {taskinstance.py:1571} INFO - Exporting the following env vars:
AIRFLOW_CTX_DAG_OWNER=***
AIRFLOW_CTX_DAG_ID=my_first_dag
AIRFLOW_CTX_TASK_ID=process_user
AIRFLOW_CTX_EXECUTION_DATE=2022-10-17T10:24:20.577359+00:00
AIRFLOW_CTX_TRY_NUMBER=1
AIRFLOW_CTX_DAG_RUN_ID=manual__2022-10-17T10:24:20.577359+00:00
[2022-10-17 10:24:26,981] {taskinstance.py:1889} ERROR - Task failed with exception
Traceback (most recent call last):
  File "/home/airflow/.local/lib/python3.7/site-packages/airflow/operators/python.py", line 171, in execute
    return_value = self.execute_callable()
  File "/home/airflow/.local/lib/python3.7/site-packages/airflow/operators/python.py", line 189, in execute_callable
    return self.python_callable(*self.op_args, **self.op_kwargs)
  File "/opt/airflow/dags/user_processing.py", line 14, in _process_user
    user = user["results"][0]
KeyError: 'results'
[2022-10-17 10:24:26,988] {taskinstance.py:1400} INFO - Marking task as FAILED. dag_id=my_first_dag, task_id=process_user, execution_date=20221017T102420, start_date=20221017T102426, end_date=20221017T102426
[2022-10-17 10:24:26,995] {standard_task_runner.py:97} ERROR - Failed to execute job 80 for task process_user ('results'; 3533)
[2022-10-17 10:24:27,023] {local_task_job.py:156} INFO - Task exited with return code 1
[2022-10-17 10:24:27,053] {local_task_job.py:273} INFO - 0 downstream tasks scheduled from follow-on schedule check
