[2022-10-17 09:34:15,989] {taskinstance.py:1159} INFO - Dependencies all met for <TaskInstance: my_first_dag.is_api_available backfill__2022-09-09T00:00:00+00:00 [queued]>
[2022-10-17 09:34:16,024] {taskinstance.py:1159} INFO - Dependencies all met for <TaskInstance: my_first_dag.is_api_available backfill__2022-09-09T00:00:00+00:00 [queued]>
[2022-10-17 09:34:16,029] {taskinstance.py:1356} INFO - 
--------------------------------------------------------------------------------
[2022-10-17 09:34:16,030] {taskinstance.py:1357} INFO - Starting attempt 1 of 1
[2022-10-17 09:34:16,034] {taskinstance.py:1358} INFO - 
--------------------------------------------------------------------------------
[2022-10-17 09:34:16,078] {taskinstance.py:1377} INFO - Executing <Task(HttpSensor): is_api_available> on 2022-09-09 00:00:00+00:00
[2022-10-17 09:34:16,107] {standard_task_runner.py:52} INFO - Started process 1049 to run task
[2022-10-17 09:34:16,140] {standard_task_runner.py:79} INFO - Running: ['***', 'tasks', 'run', 'my_first_dag', 'is_api_available', 'backfill__2022-09-09T00:00:00+00:00', '--job-id', '44', '--pool', 'default_pool', '--raw', '--subdir', 'DAGS_FOLDER/user_processing.py', '--cfg-path', '/tmp/tmpn43b66_g', '--error-file', '/tmp/tmpi7chzbwk']
[2022-10-17 09:34:16,144] {standard_task_runner.py:80} INFO - Job 44: Subtask is_api_available
[2022-10-17 09:34:16,410] {task_command.py:369} INFO - Running <TaskInstance: my_first_dag.is_api_available backfill__2022-09-09T00:00:00+00:00 [running]> on host 48b5b9061ccc
[2022-10-17 09:34:16,635] {taskinstance.py:1571} INFO - Exporting the following env vars:
AIRFLOW_CTX_DAG_OWNER=***
AIRFLOW_CTX_DAG_ID=my_first_dag
AIRFLOW_CTX_TASK_ID=is_api_available
AIRFLOW_CTX_EXECUTION_DATE=2022-09-09T00:00:00+00:00
AIRFLOW_CTX_TRY_NUMBER=1
AIRFLOW_CTX_DAG_RUN_ID=backfill__2022-09-09T00:00:00+00:00
[2022-10-17 09:34:16,640] {http.py:97} INFO - Poking: api/
[2022-10-17 09:34:16,734] {taskinstance.py:1889} ERROR - Task failed with exception
Traceback (most recent call last):
  File "/home/airflow/.local/lib/python3.7/site-packages/airflow/sensors/base.py", line 277, in execute
    poke_return = self.poke(context)
  File "/home/airflow/.local/lib/python3.7/site-packages/airflow/providers/http/sensors/http.py", line 112, in poke
    raise exc
  File "/home/airflow/.local/lib/python3.7/site-packages/airflow/providers/http/sensors/http.py", line 103, in poke
    extra_options=self.extra_options,
  File "/home/airflow/.local/lib/python3.7/site-packages/airflow/providers/http/hooks/http.py", line 114, in run
    session = self.get_conn(headers)
  File "/home/airflow/.local/lib/python3.7/site-packages/airflow/providers/http/hooks/http.py", line 68, in get_conn
    conn = self.get_connection(self.http_conn_id)
  File "/home/airflow/.local/lib/python3.7/site-packages/airflow/hooks/base.py", line 67, in get_connection
    conn = Connection.get_connection_from_secrets(conn_id)
  File "/home/airflow/.local/lib/python3.7/site-packages/airflow/models/connection.py", line 430, in get_connection_from_secrets
    raise AirflowNotFoundException(f"The conn_id `{conn_id}` isn't defined")
airflow.exceptions.AirflowNotFoundException: The conn_id `user_api` isn't defined
[2022-10-17 09:34:16,799] {taskinstance.py:1400} INFO - Marking task as FAILED. dag_id=my_first_dag, task_id=is_api_available, execution_date=20220909T000000, start_date=20221017T093415, end_date=20221017T093416
[2022-10-17 09:34:16,849] {standard_task_runner.py:97} ERROR - Failed to execute job 44 for task is_api_available (The conn_id `user_api` isn't defined; 1049)
[2022-10-17 09:34:16,965] {local_task_job.py:156} INFO - Task exited with return code 1
[2022-10-17 09:34:17,092] {local_task_job.py:273} INFO - 0 downstream tasks scheduled from follow-on schedule check
