[2022-10-13 11:53:26,312] {taskinstance.py:1159} INFO - Dependencies all met for <TaskInstance: my_first_dag.create_table scheduled__2022-10-12T00:00:00+00:00 [queued]>
[2022-10-13 11:53:26,322] {taskinstance.py:1159} INFO - Dependencies all met for <TaskInstance: my_first_dag.create_table scheduled__2022-10-12T00:00:00+00:00 [queued]>
[2022-10-13 11:53:26,323] {taskinstance.py:1356} INFO - 
--------------------------------------------------------------------------------
[2022-10-13 11:53:26,323] {taskinstance.py:1357} INFO - Starting attempt 1 of 1
[2022-10-13 11:53:26,324] {taskinstance.py:1358} INFO - 
--------------------------------------------------------------------------------
[2022-10-13 11:53:26,338] {taskinstance.py:1377} INFO - Executing <Task(PostgresOperator): create_table> on 2022-10-12 00:00:00+00:00
[2022-10-13 11:53:26,343] {standard_task_runner.py:52} INFO - Started process 82 to run task
[2022-10-13 11:53:26,347] {standard_task_runner.py:79} INFO - Running: ['***', 'tasks', 'run', 'my_first_dag', 'create_table', 'scheduled__2022-10-12T00:00:00+00:00', '--job-id', '4', '--raw', '--subdir', 'DAGS_FOLDER/user_processing.py', '--cfg-path', '/tmp/tmpss8559v_', '--error-file', '/tmp/tmp549_8q4z']
[2022-10-13 11:53:26,348] {standard_task_runner.py:80} INFO - Job 4: Subtask create_table
[2022-10-13 11:53:26,429] {task_command.py:369} INFO - Running <TaskInstance: my_first_dag.create_table scheduled__2022-10-12T00:00:00+00:00 [running]> on host bfbb62eba460
[2022-10-13 11:53:26,489] {taskinstance.py:1571} INFO - Exporting the following env vars:
AIRFLOW_CTX_DAG_OWNER=***
AIRFLOW_CTX_DAG_ID=my_first_dag
AIRFLOW_CTX_TASK_ID=create_table
AIRFLOW_CTX_EXECUTION_DATE=2022-10-12T00:00:00+00:00
AIRFLOW_CTX_TRY_NUMBER=1
AIRFLOW_CTX_DAG_RUN_ID=scheduled__2022-10-12T00:00:00+00:00
[2022-10-13 11:53:26,508] {taskinstance.py:1889} ERROR - Task failed with exception
Traceback (most recent call last):
  File "/home/airflow/.local/lib/python3.7/site-packages/airflow/providers/postgres/operators/postgres.py", line 92, in execute
    self.hook.run(self.sql, self.autocommit, parameters=self.parameters)
  File "/home/airflow/.local/lib/python3.7/site-packages/airflow/hooks/dbapi.py", line 181, in run
    with closing(self.get_conn()) as conn:
  File "/home/airflow/.local/lib/python3.7/site-packages/airflow/providers/postgres/hooks/postgres.py", line 86, in get_conn
    conn = deepcopy(self.connection or self.get_connection(conn_id))
  File "/home/airflow/.local/lib/python3.7/site-packages/airflow/hooks/base.py", line 67, in get_connection
    conn = Connection.get_connection_from_secrets(conn_id)
  File "/home/airflow/.local/lib/python3.7/site-packages/airflow/models/connection.py", line 430, in get_connection_from_secrets
    raise AirflowNotFoundException(f"The conn_id `{conn_id}` isn't defined")
airflow.exceptions.AirflowNotFoundException: The conn_id `postgres` isn't defined
[2022-10-13 11:53:26,511] {taskinstance.py:1400} INFO - Marking task as FAILED. dag_id=my_first_dag, task_id=create_table, execution_date=20221012T000000, start_date=20221013T115326, end_date=20221013T115326
[2022-10-13 11:53:26,522] {standard_task_runner.py:97} ERROR - Failed to execute job 4 for task create_table (The conn_id `postgres` isn't defined; 82)
[2022-10-13 11:53:26,568] {local_task_job.py:156} INFO - Task exited with return code 1
[2022-10-13 11:53:26,601] {local_task_job.py:273} INFO - 0 downstream tasks scheduled from follow-on schedule check
